<sdf version='1.7'>
  <world name='default'>
    <light name='sun' type='directional'>
      <cast_shadows>1</cast_shadows>
      <pose>0 0 10 0 -0 0</pose>
      <diffuse>0.8 0.8 0.8 1</diffuse>
      <specular>0.2 0.2 0.2 1</specular>
      <attenuation>
        <range>1000</range>
        <constant>0.9</constant>
        <linear>0.01</linear>
        <quadratic>0.001</quadratic>
      </attenuation>
      <direction>-0.5 0.1 -0.9</direction>
      <spot>
        <inner_angle>0</inner_angle>
        <outer_angle>0</outer_angle>
        <falloff>0</falloff>
      </spot>
    </light>
    <model name='ground_plane'>
      <static>1</static>
      <link name='link'>
        <collision name='collision'>
          <geometry>
            <plane>
              <normal>0 0 1</normal>
              <size>100 100</size>
            </plane>
          </geometry>
          <surface>
            <contact>
              <collide_bitmask>65535</collide_bitmask>
              <ode/>
            </contact>
            <friction>
              <ode>
                <mu>100</mu>
                <mu2>50</mu2>
              </ode>
              <torsional>
                <ode/>
              </torsional>
            </friction>
            <bounce/>
          </surface>
          <max_contacts>10</max_contacts>
        </collision>
        <visual name='visual'>
          <cast_shadows>0</cast_shadows>
          <geometry>
            <plane>
              <normal>0 0 1</normal>
              <size>100 100</size>
            </plane>
          </geometry>
          <material>
            <script>
              <uri>file://media/materials/scripts/gazebo.material</uri>
              <name>Gazebo/Grey</name>
            </script>
          </material>
        </visual>
        <self_collide>0</self_collide>
        <enable_wind>0</enable_wind>
        <kinematic>0</kinematic>
      </link>
    </model>
    <gravity>0 0 -9.8</gravity>
    <magnetic_field>6e-06 2.3e-05 -4.2e-05</magnetic_field>
    <atmosphere type='adiabatic'/>
    <physics type='ode'>
      <max_step_size>0.001</max_step_size>
      <real_time_factor>1</real_time_factor>
      <real_time_update_rate>1000</real_time_update_rate>
    </physics>
    <scene>
      <ambient>0.4 0.4 0.4 1</ambient>
      <background>0.7 0.7 0.7 1</background>
      <shadows>1</shadows>
    </scene>
    <audio>
      <device>default</device>
    </audio>
    <wind/>
    <spherical_coordinates>
      <surface_model>EARTH_WGS84</surface_model>
      <latitude_deg>0</latitude_deg>
      <longitude_deg>0</longitude_deg>
      <elevation>0</elevation>
      <heading_deg>0</heading_deg>
    </spherical_coordinates>
    <model name='my_robot'>
      <static>0</static>
      <link name='chassis'>
        <pose>0 0 0.1 0 -0 0</pose>
        <collision name='collision'>
          <geometry>
            <cylinder>
              <radius>0.18</radius>
              <length>0.08</length>
            </cylinder>
          </geometry>
          <max_contacts>10</max_contacts>
          <surface>
            <contact>
              <ode/>
            </contact>
            <bounce/>
            <friction>
              <torsional>
                <ode/>
              </torsional>
              <ode/>
            </friction>
          </surface>
        </collision>
        <visual name='visual'>
          <geometry>
            <cylinder>
              <radius>0.18</radius>
              <length>0.08</length>
            </cylinder>
          </geometry>
        </visual>
        <collision name='hinge1_collision'>
          <pose>0 0.021 0.06 0 -0 0</pose>
          <geometry>
            <box>
              <size>0.06 0.02 0.06</size>
            </box>
          </geometry>
          <max_contacts>10</max_contacts>
          <surface>
            <contact>
              <ode/>
            </contact>
            <bounce/>
            <friction>
              <torsional>
                <ode/>
              </torsional>
              <ode/>
            </friction>
          </surface>
        </collision>
        <visual name='hinge1_visual'>
          <pose>0 0.021 0.06 0 -0 0</pose>
          <geometry>
            <box>
              <size>0.06 0.02 0.06</size>
            </box>
          </geometry>
        </visual>
        <collision name='hinge2_collision'>
          <pose>0 -0.021 0.06 0 -0 0</pose>
          <geometry>
            <box>
              <size>0.06 0.02 0.06</size>
            </box>
          </geometry>
          <max_contacts>10</max_contacts>
          <surface>
            <contact>
              <ode/>
            </contact>
            <bounce/>
            <friction>
              <torsional>
                <ode/>
              </torsional>
              <ode/>
            </friction>
          </surface>
        </collision>
        <visual name='hinge2_visual'>
          <pose>0 -0.021 0.06 0 -0 0</pose>
          <geometry>
            <box>
              <size>0.06 -0.02 0.06</size>
            </box>
          </geometry>
        </visual>
        <collision name='joint_collision'>
          <pose>0.12 0 -0.04 0 -0 0</pose>
          <geometry>
            <sphere>
              <radius>0.06</radius>
            </sphere>
          </geometry>
          <surface>
            <friction>
              <ode>
                <mu>0</mu>
                <mu2>0</mu2>
                <slip1>1</slip1>
                <slip2>1</slip2>
              </ode>
              <torsional>
                <ode/>
              </torsional>
            </friction>
            <contact>
              <ode/>
            </contact>
            <bounce/>
          </surface>
          <max_contacts>10</max_contacts>
        </collision>
        <visual name='caster_visual'>
          <pose>0.12 0 -0.04 0 -0 0</pose>
          <geometry>
            <sphere>
              <radius>0.06</radius>
            </sphere>
          </geometry>
        </visual>
        <collision name='joint2_collision'>
          <pose>-0.12 0 -0.04 0 -0 0</pose>
          <geometry>
            <sphere>
              <radius>0.06</radius>
            </sphere>
          </geometry>
          <surface>
            <friction>
              <ode>
                <mu>0</mu>
                <mu2>0</mu2>
                <slip1>1</slip1>
                <slip2>1</slip2>
              </ode>
              <torsional>
                <ode/>
              </torsional>
            </friction>
            <contact>
              <ode/>
            </contact>
            <bounce/>
          </surface>
          <max_contacts>10</max_contacts>
        </collision>
        <visual name='caster2_visual'>
          <pose>-0.12 0 -0.04 0 -0 0</pose>
          <geometry>
            <sphere>
              <radius>0.06</radius>
            </sphere>
          </geometry>
        </visual>
        <self_collide>0</self_collide>
        <inertial>
          <pose>0 0 0 0 -0 0</pose>
          <inertia>
            <ixx>1</ixx>
            <ixy>0</ixy>
            <ixz>0</ixz>
            <iyy>1</iyy>
            <iyz>0</iyz>
            <izz>1</izz>
          </inertia>
          <mass>1</mass>
        </inertial>
        <enable_wind>0</enable_wind>
        <kinematic>0</kinematic>
      </link>
      <link name='left_wheel'>
        <pose>0 0.206 0.08 -0 1.5707 1.5707</pose>
        <collision name='collision'>
          <geometry>
            <cylinder>
              <radius>0.08</radius>
              <length>0.05</length>
            </cylinder>
          </geometry>
          <max_contacts>10</max_contacts>
          <surface>
            <contact>
              <ode/>
            </contact>
            <bounce/>
            <friction>
              <torsional>
                <ode/>
              </torsional>
              <ode/>
            </friction>
          </surface>
        </collision>
        <visual name='visual'>
          <geometry>
            <cylinder>
              <radius>0.08</radius>
              <length>0.05</length>
            </cylinder>
          </geometry>
        </visual>
        <self_collide>0</self_collide>
        <inertial>
          <pose>0 0 0 0 -0 0</pose>
          <inertia>
            <ixx>1</ixx>
            <ixy>0</ixy>
            <ixz>0</ixz>
            <iyy>1</iyy>
            <iyz>0</iyz>
            <izz>1</izz>
          </inertia>
          <mass>1</mass>
        </inertial>
        <enable_wind>0</enable_wind>
        <kinematic>0</kinematic>
      </link>
      <link name='right_wheel'>
        <pose>0 -0.206 0.08 -0 1.5707 1.5707</pose>
        <collision name='collision'>
          <geometry>
            <cylinder>
              <radius>0.08</radius>
              <length>0.05</length>
            </cylinder>
          </geometry>
          <max_contacts>10</max_contacts>
          <surface>
            <contact>
              <ode/>
            </contact>
            <bounce/>
            <friction>
              <torsional>
                <ode/>
              </torsional>
              <ode/>
            </friction>
          </surface>
        </collision>
        <visual name='visual'>
          <geometry>
            <cylinder>
              <radius>0.08</radius>
              <length>0.05</length>
            </cylinder>
          </geometry>
        </visual>
        <self_collide>0</self_collide>
        <inertial>
          <pose>0 0 0 0 -0 0</pose>
          <inertia>
            <ixx>1</ixx>
            <ixy>0</ixy>
            <ixz>0</ixz>
            <iyy>1</iyy>
            <iyz>0</iyz>
            <izz>1</izz>
          </inertia>
          <mass>1</mass>
        </inertial>
        <enable_wind>0</enable_wind>
        <kinematic>0</kinematic>
      </link>
      <link name='lower_arm'>
        <gravity>0</gravity>
        <collision name='arm1_collision'>
          <pose>0 0 0.3 0 -0 0</pose>
          <geometry>
            <box>
              <size>0.04 0.02 0.3</size>
            </box>
          </geometry>
          <max_contacts>10</max_contacts>
          <surface>
            <contact>
              <ode/>
            </contact>
            <bounce/>
            <friction>
              <torsional>
                <ode/>
              </torsional>
              <ode/>
            </friction>
          </surface>
        </collision>
        <self_collide>1</self_collide>
        <visual name='arm1_visual'>
          <pose>0 0 0.3 0 -0 0</pose>
          <geometry>
            <box>
              <size>0.04 0.02 0.3</size>
            </box>
          </geometry>
        </visual>
        <inertial>
          <pose>0 0 0 0 -0 0</pose>
          <inertia>
            <ixx>1</ixx>
            <ixy>0</ixy>
            <ixz>0</ixz>
            <iyy>1</iyy>
            <iyz>0</iyz>
            <izz>1</izz>
          </inertia>
          <mass>1</mass>
        </inertial>
        <enable_wind>0</enable_wind>
        <kinematic>0</kinematic>
        <mass>0.10</mass>
        <inertia>
          <ixx>0.001</ixx>
          <ixy>0.001</ixy>
          <ixz>0.001</ixz>
          <iyy>0.001</iyy>
          <iyz>0.001</iyz>
          <izz>0.001</izz>
        </inertia>
      </link>
      <link name='upper_arm'>
        <gravity>0</gravity>
        <collision name='arm2_collision'>
          <pose>0.13 0.02 0.43 0 -0 0</pose>
          <geometry>
            <box>
              <size>0.3 0.02 0.04</size>
            </box>
          </geometry>
          <max_contacts>10</max_contacts>
          <surface>
            <contact>
              <ode/>
            </contact>
            <bounce/>
            <friction>
              <torsional>
                <ode/>
              </torsional>
              <ode/>
            </friction>
          </surface>
        </collision>
        <self_collide>1</self_collide>
        <visual name='arm2_visual'>
          <pose>0.13 0.02 0.43 0 -0 0</pose>
          <geometry>
            <box>
              <size>0.3 0.02 0.04</size>
            </box>
          </geometry>
        </visual>
        <inertial>
          <pose>0 0 0 0 -0 0</pose>
          <inertia>
            <ixx>1</ixx>
            <ixy>0</ixy>
            <ixz>0</ixz>
            <iyy>1</iyy>
            <iyz>0</iyz>
            <izz>1</izz>
          </inertia>
          <mass>1</mass>
        </inertial>
        <enable_wind>0</enable_wind>
        <kinematic>0</kinematic>
        <mass>0.10</mass>
        <inertia>
          <ixx>0.001</ixx>
          <ixy>0.001</ixy>
          <ixz>0.001</ixz>
          <iyy>0.001</iyy>
          <iyz>0.001</iyz>
          <izz>0.001</izz>
        </inertia>
      </link>
      <joint name='left_wheel_hinge' type='revolute'>
        <pose>0 0 -0.02 0 -0 0</pose>
        <child>left_wheel</child>
        <parent>chassis</parent>
        <axis>
          <xyz expressed_in='__model__'>0 1 0</xyz>
          <limit>
            <lower>-1e+16</lower>
            <upper>1e+16</upper>
          </limit>
          <dynamics>
            <spring_reference>0</spring_reference>
            <spring_stiffness>0</spring_stiffness>
          </dynamics>
        </axis>
      </joint>
      <joint name='right_wheel_hinge' type='revolute'>
        <pose>0 0 0.02 0 -0 0</pose>
        <child>right_wheel</child>
        <parent>chassis</parent>
        <axis>
          <xyz expressed_in='__model__'>0 1 0</xyz>
          <limit>
            <lower>-1e+16</lower>
            <upper>1e+16</upper>
          </limit>
          <dynamics>
            <spring_reference>0</spring_reference>
            <spring_stiffness>0</spring_stiffness>
          </dynamics>
        </axis>
      </joint>
      <joint name='lower_arm_hinge' type='revolute'>
        <pose>0 0 0.17 0 -0 0</pose>
        <child>lower_arm</child>
        <parent>chassis</parent>
        <axis>
          <xyz expressed_in='__model__'>0 1 0</xyz>
          <limit>
            <lower>-1e+16</lower>
            <upper>1e+16</upper>
          </limit>
          <dynamics>
            <spring_reference>0</spring_reference>
            <spring_stiffness>0</spring_stiffness>
          </dynamics>
        </axis>
        <origin xyz='0 0 0.17' rpy='0 0 0'/>
        <dynamics damping='0.7'/>
        <limit lower='0' upper='1.50'/>
      </joint>
      <joint name='upper_arm_hinge' type='revolute'>
        <pose>0 0 0.43 0 -0 0</pose>
        <child>upper_arm</child>
        <parent>lower_arm</parent>
        <axis>
          <xyz expressed_in='__model__'>0 1 0</xyz>
          <limit>
            <lower>-1e+16</lower>
            <upper>1e+16</upper>
          </limit>
          <dynamics>
            <spring_reference>0</spring_reference>
            <spring_stiffness>0</spring_stiffness>
          </dynamics>
        </axis>
        <origin xyz='0 0 0.43' rpy='0 0 0'/>
        <dynamics damping='0.7'/>
        <limit lower='-1.50' upper='0'/>
      </joint>
      <pose>0.978331 0.83867 0 0 -0 0</pose>
      <gazebo>
        <plugin name='gazebo_ros_control' filename='libgazebo_ros_control.so'>
          <robotNamespace>/our_robot</robotNamespace>
        </plugin>
      </gazebo>
      <transmission name='left_wheel_trans'>
        <type>transmission_interface/Simpletransmission</type>
        <actuator name='motor1'>
          <mechanicalReduction>1</mechanicalReduction>
        </actuator>
        <joint name='left_wheel_hinge'>
          <hardwareInterface>EffortJointInterface</hardwareInterface>
        </joint>
      </transmission>
    </model>
    <model name='obstacle'>
      <pose>1.51296 2.4167 0.5 0 -0 0</pose>
      <link name='link'>
        <inertial>
          <mass>1</mass>
          <inertia>
            <ixx>0.145833</ixx>
            <ixy>0</ixy>
            <ixz>0</ixz>
            <iyy>0.145833</iyy>
            <iyz>0</iyz>
            <izz>0.125</izz>
          </inertia>
          <pose>0 0 0 0 -0 0</pose>
        </inertial>
        <collision name='collision'>
          <geometry>
            <cylinder>
              <radius>0.5</radius>
              <length>1</length>
            </cylinder>
          </geometry>
          <surface>
            <contact>
              <ode/>
            </contact>
            <bounce/>
            <friction>
              <torsional>
                <ode/>
              </torsional>
              <ode/>
            </friction>
          </surface>
          <max_contacts>10</max_contacts>
        </collision>
        <visual name='visual'>
          <geometry>
            <cylinder>
              <radius>0.5</radius>
              <length>1</length>
            </cylinder>
          </geometry>
          <material>
            <script>
              <name>Gazebo/Grey</name>
              <uri>file://media/materials/scripts/gazebo.material</uri>
            </script>
          </material>
        </visual>
        <self_collide>0</self_collide>
        <enable_wind>0</enable_wind>
        <kinematic>0</kinematic>
      </link>
    </model>
    <model name='obstacle_1'>
      <pose>4.47825 2.69999 0.5 0 -0 0</pose>
      <link name='link'>
        <inertial>
          <mass>1</mass>
          <inertia>
            <ixx>0.145833</ixx>
            <ixy>0</ixy>
            <ixz>0</ixz>
            <iyy>0.145833</iyy>
            <iyz>0</iyz>
            <izz>0.125</izz>
          </inertia>
          <pose>0 0 0 0 -0 0</pose>
        </inertial>
        <collision name='collision'>
          <geometry>
            <cylinder>
              <radius>0.5</radius>
              <length>0.678686</length>
            </cylinder>
          </geometry>
          <surface>
            <contact>
              <ode/>
            </contact>
            <bounce/>
            <friction>
              <torsional>
                <ode/>
              </torsional>
              <ode/>
            </friction>
          </surface>
          <max_contacts>10</max_contacts>
        </collision>
        <visual name='visual'>
          <geometry>
            <cylinder>
              <radius>0.5</radius>
              <length>0.678686</length>
            </cylinder>
          </geometry>
          <material>
            <script>
              <name>Gazebo/Grey</name>
              <uri>file://media/materials/scripts/gazebo.material</uri>
            </script>
          </material>
        </visual>
        <self_collide>0</self_collide>
        <enable_wind>0</enable_wind>
        <kinematic>0</kinematic>
      </link>
    </model>
    <model name='obstacle_2'>
      <pose>2.92087 3.56763 0.5 0 -0 0</pose>
      <link name='link'>
        <inertial>
          <mass>1</mass>
          <inertia>
            <ixx>0.145833</ixx>
            <ixy>0</ixy>
            <ixz>0</ixz>
            <iyy>0.145833</iyy>
            <iyz>0</iyz>
            <izz>0.125</izz>
          </inertia>
          <pose>0 0 0 0 -0 0</pose>
        </inertial>
        <collision name='collision'>
          <geometry>
            <cylinder>
              <radius>0.229835</radius>
              <length>0.452769</length>
            </cylinder>
          </geometry>
          <surface>
            <contact>
              <ode/>
            </contact>
            <bounce/>
            <friction>
              <torsional>
                <ode/>
              </torsional>
              <ode/>
            </friction>
          </surface>
          <max_contacts>10</max_contacts>
        </collision>
        <visual name='visual'>
          <geometry>
            <cylinder>
              <radius>0.229835</radius>
              <length>0.452769</length>
            </cylinder>
          </geometry>
          <material>
            <script>
              <name>Gazebo/Grey</name>
              <uri>file://media/materials/scripts/gazebo.material</uri>
            </script>
          </material>
        </visual>
        <self_collide>0</self_collide>
        <enable_wind>0</enable_wind>
        <kinematic>0</kinematic>
      </link>
    </model>
    <model name='obstacle_3'>
      <pose>2.15929 1.09281 0.5 0 0 -0.02837</pose>
      <link name='link'>
        <inertial>
          <mass>1</mass>
          <inertia>
            <ixx>0.145833</ixx>
            <ixy>0</ixy>
            <ixz>0</ixz>
            <iyy>0.145833</iyy>
            <iyz>0</iyz>
            <izz>0.125</izz>
          </inertia>
          <pose>0 0 0 0 -0 0</pose>
        </inertial>
        <collision name='collision'>
          <geometry>
            <cylinder>
              <radius>1.28006</radius>
              <length>1</length>
            </cylinder>
          </geometry>
          <surface>
            <contact>
              <ode/>
            </contact>
            <bounce/>
            <friction>
              <torsional>
                <ode/>
              </torsional>
              <ode/>
            </friction>
          </surface>
          <max_contacts>10</max_contacts>
        </collision>
        <visual name='visual'>
          <geometry>
            <cylinder>
              <radius>1.28006</radius>
              <length>1</length>
            </cylinder>
          </geometry>
          <material>
            <script>
              <name>Gazebo/Grey</name>
              <uri>file://media/materials/scripts/gazebo.material</uri>
            </script>
          </material>
        </visual>
        <self_collide>0</self_collide>
        <enable_wind>0</enable_wind>
        <kinematic>0</kinematic>
      </link>
    </model>
    <model name='goal_stand_full'>
      <pose>3.93154 0.874389 0.5 0 -0 0</pose>
      <link name='link'>
        <inertial>
          <mass>1</mass>
          <inertia>
            <ixx>0.145833</ixx>
            <ixy>0</ixy>
            <ixz>0</ixz>
            <iyy>0.145833</iyy>
            <iyz>0</iyz>
            <izz>0.125</izz>
          </inertia>
          <pose>0 0 0 0 -0 0</pose>
        </inertial>
        <collision name='collision'>
          <geometry>
            <cylinder>
              <radius>0.882075</radius>
              <length>2.81399</length>
            </cylinder>
          </geometry>
          <surface>
            <contact>
              <ode/>
            </contact>
            <bounce/>
            <friction>
              <torsional>
                <ode/>
              </torsional>
              <ode/>
            </friction>
          </surface>
          <max_contacts>10</max_contacts>
        </collision>
        <visual name='visual'>
          <geometry>
            <cylinder>
              <radius>0.882075</radius>
              <length>2.81399</length>
            </cylinder>
          </geometry>
          <material>
            <ambient>0 1 1 0.1</ambient>
            <diffuse>0.1 0.1 0.2 1</diffuse>
            <specular>0 0 0 0</specular>
            <emissive>0 0 0 1</emissive>
          </material>
        </visual>
        <self_collide>0</self_collide>
        <enable_wind>0</enable_wind>
        <kinematic>0</kinematic>
      </link>
      <enable_wind>0</enable_wind>
    </model>
    <model name='goal_stand_empty'>
      <pose>7.68976 0.92159 0.177677 0 -0 3.8e-05</pose>
      <link name='link'>
        <inertial>
          <mass>1</mass>
          <inertia>
            <ixx>0.145833</ixx>
            <ixy>0</ixy>
            <ixz>0</ixz>
            <iyy>0.145833</iyy>
            <iyz>0</iyz>
            <izz>0.125</izz>
          </inertia>
          <pose>0 0 0 0 -0 0</pose>
        </inertial>
        <collision name='collision'>
          <geometry>
            <cylinder>
              <radius>0.28342</radius>
              <length>0.355373</length>
            </cylinder>
          </geometry>
          <surface>
            <contact>
              <ode/>
            </contact>
            <bounce/>
            <friction>
              <torsional>
                <ode/>
              </torsional>
              <ode/>
            </friction>
          </surface>
          <max_contacts>10</max_contacts>
        </collision>
        <visual name='visual'>
          <geometry>
            <cylinder>
              <radius>0.28342</radius>
              <length>0.355373</length>
            </cylinder>
          </geometry>
          <material>
            <ambient>1 0.1 0.1 1</ambient>
            <diffuse>0.1 0.1 0.2 1</diffuse>
            <specular>0 0 0 0</specular>
            <emissive>0 0 0 1</emissive>
          </material>
        </visual>
        <self_collide>0</self_collide>
        <enable_wind>0</enable_wind>
        <kinematic>0</kinematic>
      </link>
    </model>
    <state world_name='default'>
      <sim_time>158 533000000</sim_time>
      <real_time>53 363097574</real_time>
      <wall_time>1638792280 90344409</wall_time>
      <iterations>53182</iterations>
      <model name='goal_stand_empty'>
        <pose>7.68976 0.92159 0.177677 0 -0 3.8e-05</pose>
        <scale>1 1 1</scale>
        <link name='link'>
          <pose>7.68976 0.92159 0.177677 0 -0 3.8e-05</pose>
          <velocity>0 0 0 0 -0 0</velocity>
          <acceleration>0 0 -9.8 0 -0 0</acceleration>
          <wrench>0 0 -9.8 0 -0 0</wrench>
        </link>
      </model>
      <model name='goal_stand_full'>
        <pose>4.27918 1.00343 0.077135 0 -0 0</pose>
        <scale>0.243493 0.243493 0.05483</scale>
        <link name='link'>
          <pose>4.27918 1.00343 0.077135 0 -0 0</pose>
          <velocity>0 0 0 0 -0 0</velocity>
          <acceleration>0 0 -9.8 0 -0 0</acceleration>
          <wrench>0 0 -9.8 0 -0 0</wrench>
        </link>
      </model>
      <model name='ground_plane'>
        <pose>0 0 0 0 -0 0</pose>
        <scale>1 1 1</scale>
        <link name='link'>
          <pose>0 0 0 0 -0 0</pose>
          <velocity>0 0 0 0 -0 0</velocity>
          <acceleration>0 0 0 0 -0 0</acceleration>
          <wrench>0 0 0 0 -0 0</wrench>
        </link>
      </model>
      <model name='my_robot'>
        <pose>0.48017 1.40718 0 1e-05 3e-06 -0.022346</pose>
        <scale>1 1 1</scale>
        <link name='chassis'>
          <pose>0.48017 1.40717 0.1 1e-05 3e-06 -0.022346</pose>
          <velocity>0.000363 -8.7e-05 0.000143 0.000699 0.001373 2e-06</velocity>
          <acceleration>-0.011213 0.112847 0.44339 -1.25887 -0.540815 -0.005698</acceleration>
          <wrench>-0.011213 0.112847 0.44339 0 -0 0</wrench>
        </link>
        <link name='left_wheel'>
          <pose>0.484774 1.61312 0.080001 1.57077 0.835195 3.11909</pose>
          <velocity>0.000336 -7.1e-05 0.000518 0.000757 0.004211 2e-06</velocity>
          <acceleration>0.001325 0.08946 0.46975 -1.25204 0.028011 -0.005574</acceleration>
          <wrench>0.001325 0.08946 0.46975 0 -0 0</wrench>
        </link>
        <link name='lower_arm'>
          <pose>0.477352 1.40724 2.4e-05 1e-05 0.016581 -0.022346</pose>
          <velocity>0.000458 -1.5e-05 0.000132 0.000698 -2.8e-05 1e-06</velocity>
          <acceleration>-0.059829 -0.004289 0.431381 -1.21872 0.03119 -0.006191</acceleration>
          <wrench>-0.059829 -0.004289 0.431381 0 -0 0</wrench>
        </link>
        <link name='right_wheel'>
          <pose>0.475566 1.20123 0.08 1.57077 0.842085 3.11909</pose>
          <velocity>0.000351 -6e-05 0.00044 0.00075 0.004393 3e-06</velocity>
          <acceleration>0.012684 0.101064 1.12861 -1.26646 0.037696 -0.004996</acceleration>
          <wrench>0.012684 0.101064 1.12861 0 -0 0</wrench>
        </link>
        <link name='upper_arm'>
          <pose>0.480241 1.40717 -1.5e-05 1e-05 0.009861 -0.022346</pose>
          <velocity>0.000444 -5e-06 0.000125 0.000722 -6e-06 1e-06</velocity>
          <acceleration>-0.05184 0.004216 0.422089 -1.1985 0.002665 -0.006553</acceleration>
          <wrench>-0.05184 0.004216 0.422089 0 -0 0</wrench>
        </link>
      </model>
      <model name='obstacle'>
        <pose>0.547241 5.50256 0.499992 -3e-06 -4e-06 -0</pose>
        <scale>1 1 1</scale>
        <link name='link'>
          <pose>0.547241 5.50256 0.499992 -3e-06 -4e-06 -0</pose>
          <velocity>0 0 0 0 -0 0</velocity>
          <acceleration>0 0 -9.8 0 -0 0</acceleration>
          <wrench>0 0 -9.8 0 -0 0</wrench>
        </link>
      </model>
      <model name='obstacle_1'>
        <pose>2.45977 2.84271 0.499998 0 -0 0.023646</pose>
        <scale>1 1 1.47343</scale>
        <link name='link'>
          <pose>2.45977 2.84271 0.499998 0 -0 0.023646</pose>
          <velocity>0 0 0 0 -0 0</velocity>
          <acceleration>0.000129 0 0 0 0.000259 0</acceleration>
          <wrench>0.000129 0 0 0 -0 0</wrench>
        </link>
      </model>
      <model name='obstacle_2'>
        <pose>4.34352 3.4438 0.49999 7e-06 8e-06 -0.026883</pose>
        <scale>5.4258 5.4258 2.20863</scale>
        <link name='link'>
          <pose>4.34352 3.4438 0.49999 7e-06 8e-06 -0.026883</pose>
          <velocity>0 0 0 0 -0 0</velocity>
          <acceleration>7.35664 -7.35229 -0.36807 -0.596461 0.597061 3.11489</acceleration>
          <wrench>7.35664 -7.35229 -0.36807 0 -0 0</wrench>
        </link>
      </model>
      <model name='obstacle_3'>
        <pose>2.27065 1.18565 0.499992 -4e-06 9e-06 0.363764</pose>
        <scale>0.849754 0.849754 1</scale>
        <link name='link'>
          <pose>2.27065 1.18565 0.499992 -4e-06 9e-06 0.363764</pose>
          <velocity>0 0 0 0 -0 0</velocity>
          <acceleration>7.96612 7.97094 1.82359 -0.331368 -0.308433 -3.13751</acceleration>
          <wrench>7.96612 7.97094 1.82359 0 -0 0</wrench>
        </link>
      </model>
      <model name='the_orb'>
        <pose>4.28763 0.939015 0.195684 0.000174 2.9e-05 -0</pose>
        <scale>0.082845 0.082845 0.082845</scale>
        <link name='link'>
          <pose>4.28763 0.939015 0.195684 0.000174 2.9e-05 -0</pose>
          <velocity>0 0 0 0 -0 0</velocity>
          <acceleration>0 0 -9.8 -0 -0 -0</acceleration>
          <wrench>0 0 -9.8 0 -0 0</wrench>
        </link>
      </model>
      <light name='sun'>
        <pose>0 0 10 0 -0 0</pose>
      </light>
    </state>
    <gui fullscreen='0'>
      <camera name='user_camera'>
        <pose>-11.4319 -17.6209 16.6202 0 0.681798 0.761413</pose>
        <view_controller>orbit</view_controller>
        <projection_type>perspective</projection_type>
      </camera>
    </gui>
    <model name='the_orb'>
      <pose>4.41156 1.22669 0.5 0 -0 0</pose>
      <link name='link'>
        <inertial>
          <mass>1</mass>
          <inertia>
            <ixx>0.1</ixx>
            <ixy>0</ixy>
            <ixz>0</ixz>
            <iyy>0.1</iyy>
            <iyz>0</iyz>
            <izz>0.1</izz>
          </inertia>
          <pose>0 0 0 0 -0 0</pose>
        </inertial>
        <collision name='collision'>
          <geometry>
            <sphere>
              <radius>0.500001</radius>
            </sphere>
          </geometry>
          <max_contacts>10</max_contacts>
          <surface>
            <contact>
              <ode/>
            </contact>
            <bounce/>
            <friction>
              <torsional>
                <ode/>
              </torsional>
              <ode/>
            </friction>
          </surface>
        </collision>
        <visual name='visual'>
          <geometry>
            <sphere>
              <radius>0.500001</radius>
            </sphere>
          </geometry>
          <material>
            <ambient>0.5 0.5 0.5 1</ambient>
            <diffuse>0.1 0.1 0.2 1</diffuse>
            <specular>0 0 0 1</specular>
            <emissive>1 1 1 1</emissive>
          </material>
        </visual>
        <self_collide>0</self_collide>
        <enable_wind>0</enable_wind>
        <kinematic>0</kinematic>
      </link>
    </model>
  </world>
</sdf>
